{
    "addition": {
        "66": "public void testCatchingAsync_Throwable() throws Exception {\n",
        "67": "  com.google.common.util.concurrent.FuturesTest testCase = new com.google.common.util.concurrent.FuturesTest();\n",
        "68": "  testCase.testCatchingAsync_Throwable();\n",
        "69": "}\n",
        "70": "\n",
        "71": "public void testCatchingAsync_fallbackGeneratesCheckedException() throws Exception {\n",
        "72": "  com.google.common.util.concurrent.FuturesTest testCase = new com.google.common.util.concurrent.FuturesTest();\n",
        "73": "  testCase.testCatchingAsync_fallbackGeneratesCheckedException();\n",
        "74": "}\n",
        "75": "\n",
        "76": "public void testCatchingAsync_fallbackGeneratesError() throws Exception {\n",
        "77": "  com.google.common.util.concurrent.FuturesTest testCase = new com.google.common.util.concurrent.FuturesTest();\n",
        "78": "  testCase.testCatchingAsync_fallbackGeneratesError();\n",
        "79": "}\n",
        "80": "\n",
        "81": "public void testCatchingAsync_fallbackGeneratesRuntimeException() throws Exception {\n",
        "82": "  com.google.common.util.concurrent.FuturesTest testCase = new com.google.common.util.concurrent.FuturesTest();\n",
        "83": "  testCase.testCatchingAsync_fallbackGeneratesRuntimeException();\n",
        "84": "}\n",
        "85": "\n",
        "86": "public void testCatchingAsync_fallbackNotReady() throws Exception {\n",
        "87": "  com.google.common.util.concurrent.FuturesTest testCase = new com.google.common.util.concurrent.FuturesTest();\n",
        "88": "  testCase.testCatchingAsync_fallbackNotReady();\n",
        "89": "}\n",
        "90": "\n",
        "91": "public void testCatchingAsync_fallbackReturnsCheckedException() throws Exception {\n",
        "92": "  com.google.common.util.concurrent.FuturesTest testCase = new com.google.common.util.concurrent.FuturesTest();\n",
        "93": "  testCase.testCatchingAsync_fallbackReturnsCheckedException();\n",
        "94": "}\n",
        "95": "\n",
        "96": "public void testCatchingAsync_fallbackReturnsRuntimeException() throws Exception {\n",
        "97": "  com.google.common.util.concurrent.FuturesTest testCase = new com.google.common.util.concurrent.FuturesTest();\n",
        "98": "  testCase.testCatchingAsync_fallbackReturnsRuntimeException();\n",
        "99": "}\n",
        "100": "\n",
        "101": "public void testCatchingAsync_inputDoesNotRaiseException() throws Exception {\n",
        "102": "  com.google.common.util.concurrent.FuturesTest testCase = new com.google.common.util.concurrent.FuturesTest();\n",
        "103": "  testCase.testCatchingAsync_inputDoesNotRaiseException();\n",
        "104": "}\n",
        "105": "\n",
        "106": "public void testCatchingAsync_inputRaisesException() throws Exception {\n",
        "107": "  com.google.common.util.concurrent.FuturesTest testCase = new com.google.common.util.concurrent.FuturesTest();\n",
        "108": "  testCase.testCatchingAsync_inputRaisesException();\n",
        "109": "}\n",
        "110": "\n",
        "111": "public void testCatchingAsync_nullInsteadOfFuture() throws Exception {\n",
        "112": "  com.google.common.util.concurrent.FuturesTest testCase = new com.google.common.util.concurrent.FuturesTest();\n",
        "113": "  testCase.testCatchingAsync_nullInsteadOfFuture();\n",
        "114": "}\n",
        "115": "\n",
        "116": "public void testCatchingAsync_resultCancelledBeforeFallback() throws Exception {\n",
        "117": "  com.google.common.util.concurrent.FuturesTest testCase = new com.google.common.util.concurrent.FuturesTest();\n",
        "118": "  testCase.testCatchingAsync_resultCancelledBeforeFallback();\n",
        "119": "}\n",
        "120": "\n",
        "121": "public void testCatchingAsync_resultInterruptedBeforeFallback() throws Exception {\n",
        "122": "  com.google.common.util.concurrent.FuturesTest testCase = new com.google.common.util.concurrent.FuturesTest();\n",
        "123": "  testCase.testCatchingAsync_resultInterruptedBeforeFallback();\n",
        "124": "}\n",
        "125": "\n",
        "126": "public void testCatching_Throwable() throws Exception {\n",
        "127": "  com.google.common.util.concurrent.FuturesTest testCase = new com.google.common.util.concurrent.FuturesTest();\n",
        "128": "  testCase.testCatching_Throwable();\n",
        "129": "}\n",
        "130": "\n",
        "131": "public void testCatching_fallbackGeneratesError() throws Exception {\n",
        "132": "  com.google.common.util.concurrent.FuturesTest testCase = new com.google.common.util.concurrent.FuturesTest();\n",
        "133": "  testCase.testCatching_fallbackGeneratesError();\n",
        "134": "}\n",
        "135": "\n",
        "136": "public void testCatching_fallbackGeneratesRuntimeException() throws Exception {\n",
        "137": "  com.google.common.util.concurrent.FuturesTest testCase = new com.google.common.util.concurrent.FuturesTest();\n",
        "138": "  testCase.testCatching_fallbackGeneratesRuntimeException();\n",
        "139": "}\n",
        "140": "\n",
        "141": "public void testCatching_inputDoesNotRaiseException() throws Exception {\n",
        "142": "  com.google.common.util.concurrent.FuturesTest testCase = new com.google.common.util.concurrent.FuturesTest();\n",
        "143": "  testCase.testCatching_inputDoesNotRaiseException();\n",
        "144": "}\n",
        "145": "\n",
        "146": "public void testCatching_inputRaisesException() throws Exception {\n",
        "147": "  com.google.common.util.concurrent.FuturesTest testCase = new com.google.common.util.concurrent.FuturesTest();\n",
        "148": "  testCase.testCatching_inputRaisesException();\n",
        "149": "}\n",
        "150": "\n",
        "151": "public void testCatching_resultCancelledBeforeFallback() throws Exception {\n",
        "152": "  com.google.common.util.concurrent.FuturesTest testCase = new com.google.common.util.concurrent.FuturesTest();\n",
        "153": "  testCase.testCatching_resultCancelledBeforeFallback();\n",
        "154": "}\n",
        "155": "\n",
        "156": "public void testCatching_resultInterruptedBeforeFallback() throws Exception {\n",
        "157": "  com.google.common.util.concurrent.FuturesTest testCase = new com.google.common.util.concurrent.FuturesTest();\n",
        "158": "  testCase.testCatching_resultInterruptedBeforeFallback();\n",
        "159": "}\n",
        "160": "\n"
    },
    "removed": {}
}